WARNING:werkzeug: * Debugger is active!
INFO:werkzeug: * Debugger PIN: 102-474-392
 * Serving Flask app 'app'
 * Debug mode: on
INFO:werkzeug:[31m[1mWARNING: This is a development server. Do not use it in a production deployment. Use a production WSGI server instead.[0m
 * Running on http://127.0.0.1:5000
INFO:werkzeug:[33mPress CTRL+C to quit[0m
INFO:werkzeug: * Restarting with stat
WARNING:werkzeug: * Debugger is active!
INFO:werkzeug: * Debugger PIN: 102-474-392
INFO:werkzeug:127.0.0.1 - - [01/Jan/2024 11:43:38] "[32mGET / HTTP/1.1[0m" 302 -
INFO:werkzeug:127.0.0.1 - - [01/Jan/2024 11:43:41] "GET /login HTTP/1.1" 200 -
INFO:werkzeug:127.0.0.1 - - [01/Jan/2024 11:44:14] "GET /login HTTP/1.1" 200 -
INFO:werkzeug:127.0.0.1 - - [01/Jan/2024 11:44:27] "GET /login HTTP/1.1" 200 -
INFO:werkzeug:127.0.0.1 - - [01/Jan/2024 11:44:39] "GET /login HTTP/1.1" 200 -
INFO:werkzeug:127.0.0.1 - - [01/Jan/2024 11:46:07] "GET /login HTTP/1.1" 200 -
INFO:werkzeug:127.0.0.1 - - [01/Jan/2024 12:32:56] "[35m[1mGET / HTTP/1.1[0m" 500 -
INFO:werkzeug:127.0.0.1 - - [01/Jan/2024 12:32:56] "[36mGET /?__debugger__=yes&cmd=resource&f=style.css HTTP/1.1[0m" 304 -
INFO:werkzeug:127.0.0.1 - - [01/Jan/2024 12:32:56] "[36mGET /?__debugger__=yes&cmd=resource&f=debugger.js HTTP/1.1[0m" 304 -
INFO:werkzeug:127.0.0.1 - - [01/Jan/2024 12:32:56] "[36mGET /?__debugger__=yes&cmd=resource&f=console.png HTTP/1.1[0m" 304 -
INFO:werkzeug:127.0.0.1 - - [01/Jan/2024 12:32:57] "[36mGET /?__debugger__=yes&cmd=resource&f=console.png HTTP/1.1[0m" 304 -
INFO:werkzeug:127.0.0.1 - - [01/Jan/2024 12:33:09] "[35m[1mGET / HTTP/1.1[0m" 500 -
INFO:werkzeug:127.0.0.1 - - [01/Jan/2024 12:33:09] "[36mGET /?__debugger__=yes&cmd=resource&f=style.css HTTP/1.1[0m" 304 -
INFO:werkzeug:127.0.0.1 - - [01/Jan/2024 12:33:09] "[36mGET /?__debugger__=yes&cmd=resource&f=debugger.js HTTP/1.1[0m" 304 -
INFO:werkzeug:127.0.0.1 - - [01/Jan/2024 12:33:09] "[36mGET /?__debugger__=yes&cmd=resource&f=console.png HTTP/1.1[0m" 304 -
INFO:werkzeug:127.0.0.1 - - [01/Jan/2024 12:33:41] "[32mGET / HTTP/1.1[0m" 302 -
INFO:werkzeug:127.0.0.1 - - [01/Jan/2024 12:33:44] "GET /login HTTP/1.1" 200 -
INFO:werkzeug:127.0.0.1 - - [01/Jan/2024 12:34:31] "POST /login HTTP/1.1" 200 -
INFO:werkzeug:127.0.0.1 - - [01/Jan/2024 12:34:31] "POST /login HTTP/1.1" 200 -
INFO:werkzeug:127.0.0.1 - - [01/Jan/2024 12:34:32] "POST /login HTTP/1.1" 200 -
INFO:werkzeug:127.0.0.1 - - [01/Jan/2024 12:34:32] "POST /login HTTP/1.1" 200 -
INFO:werkzeug:127.0.0.1 - - [01/Jan/2024 12:35:42] "POST /login HTTP/1.1" 200 -
INFO:werkzeug:127.0.0.1 - - [01/Jan/2024 12:35:44] "POST /login HTTP/1.1" 200 -
INFO:werkzeug:127.0.0.1 - - [01/Jan/2024 12:35:44] "POST /login HTTP/1.1" 200 -
INFO:werkzeug:127.0.0.1 - - [01/Jan/2024 12:36:01] "GET /login HTTP/1.1" 200 -
INFO:werkzeug:127.0.0.1 - - [01/Jan/2024 12:36:01] "[35m[1mGET / HTTP/1.1[0m" 500 -
Traceback (most recent call last):
  File "C:\Users\Dell\AppData\Local\Programs\Python\Python310\lib\site-packages\urllib3\connection.py", line 174, in _new_conn
    conn = connection.create_connection(
  File "C:\Users\Dell\AppData\Local\Programs\Python\Python310\lib\site-packages\urllib3\util\connection.py", line 72, in create_connection
    for res in socket.getaddrinfo(host, port, family, socket.SOCK_STREAM):
  File "C:\Users\Dell\AppData\Local\Programs\Python\Python310\lib\socket.py", line 955, in getaddrinfo
    for res in _socket.getaddrinfo(host, port, family, type, proto, flags):
socket.gaierror: [Errno 11001] getaddrinfo failed

During handling of the above exception, another exception occurred:

Traceback (most recent call last):
  File "C:\Users\Dell\AppData\Local\Programs\Python\Python310\lib\site-packages\urllib3\connectionpool.py", line 703, in urlopen
    httplib_response = self._make_request(
  File "C:\Users\Dell\AppData\Local\Programs\Python\Python310\lib\site-packages\urllib3\connectionpool.py", line 386, in _make_request
    self._validate_conn(conn)
  File "C:\Users\Dell\AppData\Local\Programs\Python\Python310\lib\site-packages\urllib3\connectionpool.py", line 1042, in _validate_conn
    conn.connect()
  File "C:\Users\Dell\AppData\Local\Programs\Python\Python310\lib\site-packages\urllib3\connection.py", line 358, in connect
    self.sock = conn = self._new_conn()
  File "C:\Users\Dell\AppData\Local\Programs\Python\Python310\lib\site-packages\urllib3\connection.py", line 186, in _new_conn
    raise NewConnectionError(
urllib3.exceptions.NewConnectionError: <urllib3.connection.HTTPSConnection object at 0x000001269B710C70>: Failed to establish a new connection: [Errno 11001] getaddrinfo failed

During handling of the above exception, another exception occurred:

Traceback (most recent call last):
  File "C:\Users\Dell\AppData\Local\Programs\Python\Python310\lib\site-packages\requests\adapters.py", line 489, in send
    resp = conn.urlopen(
  File "C:\Users\Dell\AppData\Local\Programs\Python\Python310\lib\site-packages\urllib3\connectionpool.py", line 787, in urlopen
    retries = retries.increment(
  File "C:\Users\Dell\AppData\Local\Programs\Python\Python310\lib\site-packages\urllib3\util\retry.py", line 592, in increment
    raise MaxRetryError(_pool, url, error or ResponseError(cause))
urllib3.exceptions.MaxRetryError: HTTPSConnectionPool(host='phovinologs.azurewebsites.net', port=443): Max retries exceeded with url: /get_file (Caused by NewConnectionError('<urllib3.connection.HTTPSConnection object at 0x000001269B710C70>: Failed to establish a new connection: [Errno 11001] getaddrinfo failed'))

During handling of the above exception, another exception occurred:

Traceback (most recent call last):
  File "C:\Users\Dell\AppData\Local\Programs\Python\Python310\lib\site-packages\flask\app.py", line 2213, in __call__
    return self.wsgi_app(environ, start_response)
  File "C:\Users\Dell\AppData\Local\Programs\Python\Python310\lib\site-packages\flask\app.py", line 2193, in wsgi_app
    response = self.handle_exception(e)
  File "C:\Users\Dell\AppData\Local\Programs\Python\Python310\lib\site-packages\flask\app.py", line 2190, in wsgi_app
    response = self.full_dispatch_request()
  File "C:\Users\Dell\AppData\Local\Programs\Python\Python310\lib\site-packages\flask\app.py", line 1486, in full_dispatch_request
    rv = self.handle_user_exception(e)
  File "C:\Users\Dell\AppData\Local\Programs\Python\Python310\lib\site-packages\flask\app.py", line 1482, in full_dispatch_request
    rv = self.preprocess_request()
  File "C:\Users\Dell\AppData\Local\Programs\Python\Python310\lib\site-packages\flask\app.py", line 1974, in preprocess_request
    rv = self.ensure_sync(before_func)()
  File "e:\CC-Project-Final\Gallery-view1\app.py", line 43, in before_request
    response = requests.post('https://phovinologs.azurewebsites.net/get_file', data={"file_content": file_content})
  File "C:\Users\Dell\AppData\Local\Programs\Python\Python310\lib\site-packages\requests\api.py", line 115, in post
    return request("post", url, data=data, json=json, **kwargs)
  File "C:\Users\Dell\AppData\Local\Programs\Python\Python310\lib\site-packages\requests\api.py", line 59, in request
    return session.request(method=method, url=url, **kwargs)
  File "C:\Users\Dell\AppData\Local\Programs\Python\Python310\lib\site-packages\requests\sessions.py", line 587, in request
    resp = self.send(prep, **send_kwargs)
  File "C:\Users\Dell\AppData\Local\Programs\Python\Python310\lib\site-packages\requests\sessions.py", line 701, in send
    r = adapter.send(request, **kwargs)
  File "C:\Users\Dell\AppData\Local\Programs\Python\Python310\lib\site-packages\requests\adapters.py", line 565, in send
    raise ConnectionError(e, request=request)
requests.exceptions.ConnectionError: HTTPSConnectionPool(host='phovinologs.azurewebsites.net', port=443): Max retries exceeded with url: /get_file (Caused by NewConnectionError('<urllib3.connection.HTTPSConnection object at 0x000001269B710C70>: Failed to establish a new connection: [Errno 11001] getaddrinfo failed'))
INFO:werkzeug:127.0.0.1 - - [01/Jan/2024 12:36:03] "[32mGET / HTTP/1.1[0m" 302 -
INFO:werkzeug:127.0.0.1 - - [01/Jan/2024 12:36:08] "[32mGET / HTTP/1.1[0m" 302 -
INFO:werkzeug:127.0.0.1 - - [01/Jan/2024 12:36:09] "[35m[1mGET /login HTTP/1.1[0m" 500 -
Traceback (most recent call last):
  File "C:\Users\Dell\AppData\Local\Programs\Python\Python310\lib\site-packages\urllib3\connection.py", line 174, in _new_conn
    conn = connection.create_connection(
  File "C:\Users\Dell\AppData\Local\Programs\Python\Python310\lib\site-packages\urllib3\util\connection.py", line 72, in create_connection
    for res in socket.getaddrinfo(host, port, family, socket.SOCK_STREAM):
  File "C:\Users\Dell\AppData\Local\Programs\Python\Python310\lib\socket.py", line 955, in getaddrinfo
    for res in _socket.getaddrinfo(host, port, family, type, proto, flags):
socket.gaierror: [Errno 11001] getaddrinfo failed

During handling of the above exception, another exception occurred:

Traceback (most recent call last):
  File "C:\Users\Dell\AppData\Local\Programs\Python\Python310\lib\site-packages\urllib3\connectionpool.py", line 703, in urlopen
    httplib_response = self._make_request(
  File "C:\Users\Dell\AppData\Local\Programs\Python\Python310\lib\site-packages\urllib3\connectionpool.py", line 386, in _make_request
    self._validate_conn(conn)
  File "C:\Users\Dell\AppData\Local\Programs\Python\Python310\lib\site-packages\urllib3\connectionpool.py", line 1042, in _validate_conn
    conn.connect()
  File "C:\Users\Dell\AppData\Local\Programs\Python\Python310\lib\site-packages\urllib3\connection.py", line 358, in connect
    self.sock = conn = self._new_conn()
  File "C:\Users\Dell\AppData\Local\Programs\Python\Python310\lib\site-packages\urllib3\connection.py", line 186, in _new_conn
    raise NewConnectionError(
urllib3.exceptions.NewConnectionError: <urllib3.connection.HTTPSConnection object at 0x000001269B711270>: Failed to establish a new connection: [Errno 11001] getaddrinfo failed

During handling of the above exception, another exception occurred:

Traceback (most recent call last):
  File "C:\Users\Dell\AppData\Local\Programs\Python\Python310\lib\site-packages\requests\adapters.py", line 489, in send
    resp = conn.urlopen(
  File "C:\Users\Dell\AppData\Local\Programs\Python\Python310\lib\site-packages\urllib3\connectionpool.py", line 787, in urlopen
    retries = retries.increment(
  File "C:\Users\Dell\AppData\Local\Programs\Python\Python310\lib\site-packages\urllib3\util\retry.py", line 592, in increment
    raise MaxRetryError(_pool, url, error or ResponseError(cause))
urllib3.exceptions.MaxRetryError: HTTPSConnectionPool(host='phovinologs.azurewebsites.net', port=443): Max retries exceeded with url: /get_file (Caused by NewConnectionError('<urllib3.connection.HTTPSConnection object at 0x000001269B711270>: Failed to establish a new connection: [Errno 11001] getaddrinfo failed'))

During handling of the above exception, another exception occurred:

Traceback (most recent call last):
  File "C:\Users\Dell\AppData\Local\Programs\Python\Python310\lib\site-packages\flask\app.py", line 2213, in __call__
    return self.wsgi_app(environ, start_response)
  File "C:\Users\Dell\AppData\Local\Programs\Python\Python310\lib\site-packages\flask\app.py", line 2193, in wsgi_app
    response = self.handle_exception(e)
  File "C:\Users\Dell\AppData\Local\Programs\Python\Python310\lib\site-packages\flask\app.py", line 2190, in wsgi_app
    response = self.full_dispatch_request()
  File "C:\Users\Dell\AppData\Local\Programs\Python\Python310\lib\site-packages\flask\app.py", line 1486, in full_dispatch_request
    rv = self.handle_user_exception(e)
  File "C:\Users\Dell\AppData\Local\Programs\Python\Python310\lib\site-packages\flask\app.py", line 1482, in full_dispatch_request
    rv = self.preprocess_request()
  File "C:\Users\Dell\AppData\Local\Programs\Python\Python310\lib\site-packages\flask\app.py", line 1974, in preprocess_request
    rv = self.ensure_sync(before_func)()
  File "e:\CC-Project-Final\Gallery-view1\app.py", line 43, in before_request
    response = requests.post('https://phovinologs.azurewebsites.net/get_file', data={"file_content": file_content})
  File "C:\Users\Dell\AppData\Local\Programs\Python\Python310\lib\site-packages\requests\api.py", line 115, in post
    return request("post", url, data=data, json=json, **kwargs)
  File "C:\Users\Dell\AppData\Local\Programs\Python\Python310\lib\site-packages\requests\api.py", line 59, in request
    return session.request(method=method, url=url, **kwargs)
  File "C:\Users\Dell\AppData\Local\Programs\Python\Python310\lib\site-packages\requests\sessions.py", line 587, in request
    resp = self.send(prep, **send_kwargs)
  File "C:\Users\Dell\AppData\Local\Programs\Python\Python310\lib\site-packages\requests\sessions.py", line 701, in send
    r = adapter.send(request, **kwargs)
  File "C:\Users\Dell\AppData\Local\Programs\Python\Python310\lib\site-packages\requests\adapters.py", line 565, in send
    raise ConnectionError(e, request=request)
requests.exceptions.ConnectionError: HTTPSConnectionPool(host='phovinologs.azurewebsites.net', port=443): Max retries exceeded with url: /get_file (Caused by NewConnectionError('<urllib3.connection.HTTPSConnection object at 0x000001269B711270>: Failed to establish a new connection: [Errno 11001] getaddrinfo failed'))
INFO:werkzeug:127.0.0.1 - - [01/Jan/2024 12:36:09] "[36mGET /login?__debugger__=yes&cmd=resource&f=style.css HTTP/1.1[0m" 304 -
INFO:werkzeug:127.0.0.1 - - [01/Jan/2024 12:36:09] "[36mGET /login?__debugger__=yes&cmd=resource&f=debugger.js HTTP/1.1[0m" 304 -
INFO:werkzeug:127.0.0.1 - - [01/Jan/2024 12:36:09] "[36mGET /login?__debugger__=yes&cmd=resource&f=console.png HTTP/1.1[0m" 304 -
INFO:werkzeug:127.0.0.1 - - [01/Jan/2024 12:36:09] "[36mGET /login?__debugger__=yes&cmd=resource&f=console.png HTTP/1.1[0m" 304 -
INFO:werkzeug:127.0.0.1 - - [01/Jan/2024 12:36:21] "[32mGET / HTTP/1.1[0m" 302 -
INFO:werkzeug:127.0.0.1 - - [01/Jan/2024 12:36:22] "GET /login HTTP/1.1" 200 -
INFO:werkzeug:127.0.0.1 - - [01/Jan/2024 12:36:33] "[35m[1mPOST /login HTTP/1.1[0m" 500 -
Traceback (most recent call last):
  File "C:\Users\Dell\AppData\Local\Programs\Python\Python310\lib\site-packages\urllib3\connectionpool.py", line 703, in urlopen
    httplib_response = self._make_request(
  File "C:\Users\Dell\AppData\Local\Programs\Python\Python310\lib\site-packages\urllib3\connectionpool.py", line 386, in _make_request
    self._validate_conn(conn)
  File "C:\Users\Dell\AppData\Local\Programs\Python\Python310\lib\site-packages\urllib3\connectionpool.py", line 1042, in _validate_conn
    conn.connect()
  File "C:\Users\Dell\AppData\Local\Programs\Python\Python310\lib\site-packages\urllib3\connection.py", line 414, in connect
    self.sock = ssl_wrap_socket(
  File "C:\Users\Dell\AppData\Local\Programs\Python\Python310\lib\site-packages\urllib3\util\ssl_.py", line 449, in ssl_wrap_socket
    ssl_sock = _ssl_wrap_socket_impl(
  File "C:\Users\Dell\AppData\Local\Programs\Python\Python310\lib\site-packages\urllib3\util\ssl_.py", line 493, in _ssl_wrap_socket_impl
    return ssl_context.wrap_socket(sock, server_hostname=server_hostname)
  File "C:\Users\Dell\AppData\Local\Programs\Python\Python310\lib\ssl.py", line 513, in wrap_socket
    return self.sslsocket_class._create(
  File "C:\Users\Dell\AppData\Local\Programs\Python\Python310\lib\ssl.py", line 1071, in _create
    self.do_handshake()
  File "C:\Users\Dell\AppData\Local\Programs\Python\Python310\lib\ssl.py", line 1342, in do_handshake
    self._sslobj.do_handshake()
ssl.SSLEOFError: EOF occurred in violation of protocol (_ssl.c:997)

During handling of the above exception, another exception occurred:

Traceback (most recent call last):
  File "C:\Users\Dell\AppData\Local\Programs\Python\Python310\lib\site-packages\requests\adapters.py", line 489, in send
    resp = conn.urlopen(
  File "C:\Users\Dell\AppData\Local\Programs\Python\Python310\lib\site-packages\urllib3\connectionpool.py", line 787, in urlopen
    retries = retries.increment(
  File "C:\Users\Dell\AppData\Local\Programs\Python\Python310\lib\site-packages\urllib3\util\retry.py", line 592, in increment
    raise MaxRetryError(_pool, url, error or ResponseError(cause))
urllib3.exceptions.MaxRetryError: HTTPSConnectionPool(host='phovinologs.azurewebsites.net', port=443): Max retries exceeded with url: /get_file (Caused by SSLError(SSLEOFError(8, 'EOF occurred in violation of protocol (_ssl.c:997)')))

During handling of the above exception, another exception occurred:

Traceback (most recent call last):
  File "C:\Users\Dell\AppData\Local\Programs\Python\Python310\lib\site-packages\flask\app.py", line 2213, in __call__
    return self.wsgi_app(environ, start_response)
  File "C:\Users\Dell\AppData\Local\Programs\Python\Python310\lib\site-packages\flask\app.py", line 2193, in wsgi_app
    response = self.handle_exception(e)
  File "C:\Users\Dell\AppData\Local\Programs\Python\Python310\lib\site-packages\flask\app.py", line 2190, in wsgi_app
    response = self.full_dispatch_request()
  File "C:\Users\Dell\AppData\Local\Programs\Python\Python310\lib\site-packages\flask\app.py", line 1486, in full_dispatch_request
    rv = self.handle_user_exception(e)
  File "C:\Users\Dell\AppData\Local\Programs\Python\Python310\lib\site-packages\flask\app.py", line 1482, in full_dispatch_request
    rv = self.preprocess_request()
  File "C:\Users\Dell\AppData\Local\Programs\Python\Python310\lib\site-packages\flask\app.py", line 1974, in preprocess_request
    rv = self.ensure_sync(before_func)()
  File "e:\CC-Project-Final\Gallery-view1\app.py", line 43, in before_request
    response = requests.post('https://phovinologs.azurewebsites.net/get_file', data={"file_content": file_content})
  File "C:\Users\Dell\AppData\Local\Programs\Python\Python310\lib\site-packages\requests\api.py", line 115, in post
    return request("post", url, data=data, json=json, **kwargs)
  File "C:\Users\Dell\AppData\Local\Programs\Python\Python310\lib\site-packages\requests\api.py", line 59, in request
    return session.request(method=method, url=url, **kwargs)
  File "C:\Users\Dell\AppData\Local\Programs\Python\Python310\lib\site-packages\requests\sessions.py", line 587, in request
    resp = self.send(prep, **send_kwargs)
  File "C:\Users\Dell\AppData\Local\Programs\Python\Python310\lib\site-packages\requests\sessions.py", line 701, in send
    r = adapter.send(request, **kwargs)
  File "C:\Users\Dell\AppData\Local\Programs\Python\Python310\lib\site-packages\requests\adapters.py", line 563, in send
    raise SSLError(e, request=request)
requests.exceptions.SSLError: HTTPSConnectionPool(host='phovinologs.azurewebsites.net', port=443): Max retries exceeded with url: /get_file (Caused by SSLError(SSLEOFError(8, 'EOF occurred in violation of protocol (_ssl.c:997)')))
INFO:werkzeug:127.0.0.1 - - [01/Jan/2024 12:36:33] "[36mGET /login?__debugger__=yes&cmd=resource&f=style.css HTTP/1.1[0m" 304 -
INFO:werkzeug:127.0.0.1 - - [01/Jan/2024 12:36:33] "[36mGET /login?__debugger__=yes&cmd=resource&f=debugger.js HTTP/1.1[0m" 304 -
INFO:werkzeug:127.0.0.1 - - [01/Jan/2024 12:36:33] "[36mGET /login?__debugger__=yes&cmd=resource&f=console.png HTTP/1.1[0m" 304 -
INFO:werkzeug:127.0.0.1 - - [01/Jan/2024 12:36:33] "[36mGET /login?__debugger__=yes&cmd=resource&f=console.png HTTP/1.1[0m" 304 -
 * Serving Flask app 'app'
 * Debug mode: on
INFO:werkzeug:[31m[1mWARNING: This is a development server. Do not use it in a production deployment. Use a production WSGI server instead.[0m
 * Running on http://127.0.0.1:5000
INFO:werkzeug:[33mPress CTRL+C to quit[0m
INFO:werkzeug: * Restarting with stat
WARNING:werkzeug: * Debugger is active!
INFO:werkzeug: * Debugger PIN: 102-474-392
INFO:werkzeug:127.0.0.1 - - [01/Jan/2024 13:08:42] "[32mGET / HTTP/1.1[0m" 302 -
INFO:werkzeug:127.0.0.1 - - [01/Jan/2024 13:08:42] "[32mGET / HTTP/1.1[0m" 302 -
INFO:werkzeug:127.0.0.1 - - [01/Jan/2024 13:08:43] "GET /login HTTP/1.1" 200 -
